<robot name='car_robot'>
    <link name='chassis'>
        <visual>
            <geometry>
                <box size="1.0 1.0 0.3"/>
            </geometry>
            <origin xyz="0.0 0.0 0.0" rpy="0.0 0.0 0.0"/>
        </visual>
        <collision>
            <geometry>
                <box size="1.0 1.0 0.3"/>
            </geometry>
            <origin xyz="0.0 0.0 0.0" rpy="0.0 0.0 0.0"/>
        </collision>
        <inertial>
            <origin xyz="0 0 0"/>
            <mass value="1.14395"/>
            <inertia ixx="0.095329" ixy="0" ixz="0" iyy="0.381317" iyz="0" izz="0.476646"/>
        </inertial>
    </link>
    <gazebo reference="chassis">
        <material>Gazebo/Blue</material>
    </gazebo>

    <link name='left_wheel'>
        <visual>
            <geometry>
                <cylinder radius="0.15" length="0.1"/>
            </geometry>
            <origin xyz="0.0 0.0 0.0" rpy="0.0 0.0 0.0"/>
        </visual>
        <collision>
            <geometry>
                <cylinder radius="0.15" length="0.1"/>
            </geometry>
            <origin xyz="0.0 0.0 0.0" rpy="0.0 0.0 0.0"/>
        </collision>
        <inertial>
            <origin xyz="0 0 0"/>
            <mass value="0.5"/>
            <inertia ixx="0.05" ixy="0" ixz="0" iyy="0.05" iyz="0" izz="0.1"/>
        </inertial>
    </link>
    <gazebo reference="left_wheel">
        <material>Gazebo/Red</material>
    </gazebo>

    <link name='right_wheel'>
        <visual>
            <geometry>
                <cylinder radius="0.15" length="0.1"/>
            </geometry>
            <origin xyz="0.0 0.0 0.0" rpy="0.0 0.0 0.0"/>
        </visual>
        <collision>
            <geometry>
                <cylinder radius="0.15" length="0.1"/>
            </geometry>
            <origin xyz="0.0 0.0 0.0" rpy="0.0 0.0 0.0"/>
        </collision>
        <inertial>
            <origin xyz="0 0 0"/>
            <mass value="0.5"/>
            <inertia ixx="0.05" ixy="0" ixz="0" iyy="0.05" iyz="0" izz="0.1"/>
        </inertial>
    </link>
    <gazebo reference="right_wheel">
        <material>Gazebo/Red</material>
    </gazebo>

    <link name='support_wheel'>
        <visual>
            <geometry>
                <sphere radius="0.1"/>
            </geometry>
            <origin xyz="0.0 0.0 0.0" rpy="0.0 0.0 0.0"/>
        </visual>
        <collision>
            <geometry>
                <sphere radius="0.1"/>
            </geometry>
            <origin xyz="0.0 0.0 0.0" rpy="0.0 0.0 0.0"/>
        </collision>
        <inertial>
            <origin xyz="0 0 0"/>
            <mass value="0.5"/>
            <inertia ixx="0.05" ixy="0" ixz="0" iyy="0.05" iyz="0" izz="0.1"/>
        </inertial>
    </link>
    <gazebo reference="support_wheel">
        <material>Gazebo/Green</material>
    </gazebo>

    <joint name="left_wheel2chassis" type="continuous">
        <parent link="chassis"/>
        <child link="left_wheel" />
        <origin xyz="-0.4 -0.55 -0.05" rpy="-1.57 0 0" />
        <axis xyz="0 0 1" />
        <dynamics damping="0.09"/>
    </joint>

    <joint name="right_wheel2chassis" type="continuous">
        <parent link="chassis"/>
        <child link="right_wheel"/>
        <origin xyz="-0.4 0.55 -0.05" rpy="-1.57 0 0" />
        <axis xyz="0 0 1" />
        <dynamics damping="0.09"/>
    </joint>

    <joint name="support_wheel2chassis" type="continuous">
        <parent link="chassis"/>
        <child link="support_wheel"/>
        <origin xyz="0.4 0 -0.1" rpy="-0 0 0" />
        <axis xyz="1 1 1" />
    </joint>

    <transmission name="left_wheel2chassis_trans">
        <type>transmission_interface/SimpleTransmission</type>
        <joint name="left_wheel2chassis">
            <hardwareInterface>hardware_interface/VelocityJointInterface</hardwareInterface>
        </joint>
        <actuator name="left_wheel2chassis_motor">
            <hardwareInterface>hardware_interface/VelocityJointInterface</hardwareInterface>
            <mechanicalReduction>1</mechanicalReduction>
        </actuator>
    </transmission>

    <transmission name="right_wheel2chassis_trans">
        <type>transmission_interface/SimpleTransmission</type>
        <joint name="right_wheel2chassis">
            <hardwareInterface>hardware_interface/VelocityJointInterface</hardwareInterface>
        </joint>
        <actuator name="right_wheel2chassis_motor">
            <hardwareInterface>hardware_interface/VelocityJointInterface</hardwareInterface>
            <mechanicalReduction>1</mechanicalReduction>
        </actuator>
    </transmission>

    <gazebo>
        <plugin name="differential_drive_controller" filename="libgazebo_ros_diff_drive.so">
            <rosDebugLevel>Debug</rosDebugLevel>
            <publishWheelTF>true</publishWheelTF>
            <robotNamespace>/</robotNamespace>
            <publishTf>1</publishTf>
            <publishWheelJointState>true</publishWheelJointState>
            <alwaysOn>true</alwaysOn>
            <updateRate>100.0</updateRate>
            <legacyMode>true</legacyMode>
            <leftJoint>left_wheel2chassis</leftJoint>
            <rightJoint>right_wheel2chassis</rightJoint>
            <wheelSeparation>1.1</wheelSeparation>
            <wheelDiameter>0.3</wheelDiameter>
            <broadcastTF>1</broadcastTF>
            <wheelTorque>30</wheelTorque>
            <wheelAcceleration>1.8</wheelAcceleration>
            <commandTopic>cmd_vel</commandTopic>
            <odometryFrame>odom</odometryFrame> 
            <odometryTopic>odom</odometryTopic>
            <robotBaseFrame>chassis</robotBaseFrame>
        </plugin>
    </gazebo>

</robot>