<robot name='car_robot'>
    <link name='chassis'>
        <pose relative_to='__model__'>0.5 0 0.4 0 0 0</pose>

        <inertial>
            <mass>1.14395</mass>
            <inertia>
                <ixx>0.095329</ixx>
                <ixy>0</ixy>
                <ixz>0</ixz>
                <iyy>0.381317</iyy>
                <iyz>0</iyz>
                <izz>0.476646</izz>
            </inertia>
        </inertial>

        <visual name='visual'>
            <geometry>
                <box>
                    <size>2.0 1.0 0.5</size>
                </box>
            </geometry>
            <material>
                <ambient>0.0 0.0 1.0 1</ambient>
                <diffuse>0.0 0.0 1.0 1</diffuse>
                <specular>0.0 0.0 1.0 1</specular>
            </material>
        </visual>

        <collision name='collision'>
            <geometry>
                <box>
                    <size>2.0 1.0 0.5</size>
                </box>
            </geometry>
        </collision>
    </link>

    <link name='left_wheel'>
        <pose relative_to="chassis">-0.5 0.6 0 -1.5707 0 0</pose>

        <inertial>
            <mass>1</mass>
            <inertia>
                <ixx>0.043333</ixx>
                <ixy>0</ixy>
                <ixz>0</ixz>
                <iyy>0.043333</iyy>
                <iyz>0</iyz>
                <izz>0.08</izz>
            </inertia>
        </inertial>

        <visual name='visual'>
            <geometry>
                <cylinder>
                    <radius>0.4</radius>
                    <length>0.2</length>
                </cylinder>
            </geometry>
            <material>
                <ambient>1.0 0.0 0.0 1</ambient>
                <diffuse>1.0 0.0 0.0 1</diffuse>
                <specular>1.0 0.0 0.0 1</specular>
            </material>
        </visual>

        <collision name='collision'>
            <geometry>
                <cylinder>
                    <radius>0.4</radius>
                    <length>0.2</length>
                </cylinder>
            </geometry>
        </collision>
    </link>
    
    <link name='right_wheel'>
        <pose relative_to="chassis">-0.5 -0.6 0 -1.5707 0 0</pose>
        <inertial>
            <mass>1</mass>
            <inertia>
                <ixx>0.043333</ixx>
                <ixy>0</ixy>
                <ixz>0</ixz>
                <iyy>0.043333</iyy>
                <iyz>0</iyz>
                <izz>0.08</izz>
            </inertia>
        </inertial>
        <visual name='visual'>
            <geometry>
                <cylinder>
                    <radius>0.4</radius>
                    <length>0.2</length>
                </cylinder>
            </geometry>
            <material>
                <ambient>1.0 0.0 0.0 1</ambient>
                <diffuse>1.0 0.0 0.0 1</diffuse>
                <specular>1.0 0.0 0.0 1</specular>
            </material>
        </visual>
        <collision name='collision'>
            <geometry>
                <cylinder>
                    <radius>0.4</radius>
                    <length>0.2</length>
                </cylinder>
            </geometry>
        </collision>
    </link>

    <frame name="caster_frame" attached_to='chassis'>
        <pose>0.8 0 -0.2 0 0 0</pose>
    </frame>

    <link name='caster'>
        <pose relative_to='caster_frame'/>
        <inertial>
            <mass>1</mass>
            <inertia>
                <ixx>0.016</ixx>
                <ixy>0</ixy>
                <ixz>0</ixz>
                <iyy>0.016</iyy>
                <iyz>0</iyz>
                <izz>0.016</izz>
            </inertia>
        </inertial>

        <visual name='visual'>
            <geometry>
                <sphere>
                    <radius>0.2</radius>
                </sphere>
            </geometry>
            <material>
                <ambient>0.0 1 0.0 1</ambient>
                <diffuse>0.0 1 0.0 1</diffuse>
                <specular>0.0 1 0.0 1</specular>
            </material>
        </visual>

        <collision name='collision'>
            <geometry>
                <sphere>
                    <radius>0.2</radius>
                </sphere>
            </geometry>
        </collision>
    </link>

    <joint name='left_wheel_joint' type='revolute'>
        <pose relative_to='left_wheel'/>
        <parent>chassis</parent>
        <child>left_wheel</child>
        <axis>
            <xyz expressed_in='__model__'>0 1 0</xyz>
            <limit>
                <lower>-1.79769e+308</lower>
                <upper>1.79769e+308</upper>
            </limit>
        </axis>
    </joint>

    <joint name='right_wheel_joint' type='revolute'>
        <pose relative_to='right_wheel'/>
        <parent>chassis</parent>
        <child>right_wheel</child>
        <axis>
            <xyz expressed_in='__model__'>0 1 0</xyz>
            <limit>
                <lower>-1.79769e+308</lower>
                <upper>1.79769e+308</upper>
            </limit>
        </axis>
    </joint>
    
    <joint name='caster_wheel' type='ball'>
        <parent>chassis</parent>
        <child>caster</child>
    </joint>
    


    <gazebo>
        <plugin name="differential_drive_controller" filename="libgazebo_ros_diff_drive.so">
            <rosDebugLevel>Debug</rosDebugLevel>
            <publishWheelTF>true</publishWheelTF>
            <robotNamespace>/</robotNamespace>
            <publishTf>1</publishTf>
            <publishWheelJointState>true</publishWheelJointState>
            <alwaysOn>true</alwaysOn>
            <updateRate>100.0</updateRate>
            <legacyMode>true</legacyMode>
            <leftJoint>left_wheel_joint</leftJoint>
            <rightJoint>right_wheel_joint</rightJoint>
            <wheelSeparation>1.2</wheelSeparation>
            <wheelDiameter>0.4</wheelDiameter>
            <broadcastTF>1</broadcastTF>
            <wheelTorque>30</wheelTorque>
            <wheelAcceleration>1.8</wheelAcceleration>
            <commandTopic>cmd_vel</commandTopic>
            <odometryFrame>odom</odometryFrame> 
            <odometryTopic>odom</odometryTopic>
            <robotBaseFrame>base_footprint</robotBaseFrame>
        </plugin>
    </gazebo>
</robot>